[2024-01-10T13:27:23.926+0000] {taskinstance.py:1957} INFO - Dependencies all met for dep_context=non-requeueable deps ti=<TaskInstance: weather_dag_2.group_a.tsk_truncate_table scheduled__2024-01-09T00:00:00+00:00 [queued]>
[2024-01-10T13:27:23.937+0000] {taskinstance.py:1957} INFO - Dependencies all met for dep_context=requeueable deps ti=<TaskInstance: weather_dag_2.group_a.tsk_truncate_table scheduled__2024-01-09T00:00:00+00:00 [queued]>
[2024-01-10T13:27:23.938+0000] {taskinstance.py:2171} INFO - Starting attempt 1 of 3
[2024-01-10T13:27:23.953+0000] {taskinstance.py:2192} INFO - Executing <Task(PostgresOperator): group_a.tsk_truncate_table> on 2024-01-09 00:00:00+00:00
[2024-01-10T13:27:23.960+0000] {standard_task_runner.py:60} INFO - Started process 2489 to run task
[2024-01-10T13:27:23.965+0000] {standard_task_runner.py:87} INFO - Running: ['***', 'tasks', 'run', 'weather_dag_2', 'group_a.tsk_truncate_table', 'scheduled__2024-01-09T00:00:00+00:00', '--job-id', '3', '--raw', '--subdir', 'DAGS_FOLDER/weather_dag.py', '--cfg-path', '/tmp/tmp93gq157i']
[2024-01-10T13:27:23.970+0000] {standard_task_runner.py:88} INFO - Job 3: Subtask group_a.tsk_truncate_table
[2024-01-10T13:27:24.051+0000] {task_command.py:423} INFO - Running <TaskInstance: weather_dag_2.group_a.tsk_truncate_table scheduled__2024-01-09T00:00:00+00:00 [running]> on host 2eb95800a276
[2024-01-10T13:27:24.137+0000] {taskinstance.py:2481} INFO - Exporting env vars: AIRFLOW_CTX_DAG_EMAIL='myemail@domain.com' AIRFLOW_CTX_DAG_OWNER='***' AIRFLOW_CTX_DAG_ID='weather_dag_2' AIRFLOW_CTX_TASK_ID='group_a.tsk_truncate_table' AIRFLOW_CTX_EXECUTION_DATE='2024-01-09T00:00:00+00:00' AIRFLOW_CTX_TRY_NUMBER='1' AIRFLOW_CTX_DAG_RUN_ID='scheduled__2024-01-09T00:00:00+00:00'
[2024-01-10T13:27:24.139+0000] {sql.py:276} INFO - Executing:  TRUNCATE TABLE city_look_up;
                    
[2024-01-10T13:27:24.157+0000] {taskinstance.py:2699} ERROR - Task failed with exception
Traceback (most recent call last):
  File "/home/airflow/.local/lib/python3.8/site-packages/airflow/models/taskinstance.py", line 433, in _execute_task
    result = execute_callable(context=context, **execute_callable_kwargs)
  File "/home/airflow/.local/lib/python3.8/site-packages/airflow/providers/common/sql/operators/sql.py", line 277, in execute
    hook = self.get_db_hook()
  File "/home/airflow/.local/lib/python3.8/site-packages/airflow/providers/common/sql/operators/sql.py", line 188, in get_db_hook
    return self._hook
  File "/usr/local/lib/python3.8/functools.py", line 967, in __get__
    val = self.func(instance)
  File "/home/airflow/.local/lib/python3.8/site-packages/airflow/providers/common/sql/operators/sql.py", line 150, in _hook
    conn = BaseHook.get_connection(conn_id)
  File "/home/airflow/.local/lib/python3.8/site-packages/airflow/hooks/base.py", line 82, in get_connection
    conn = Connection.get_connection_from_secrets(conn_id)
  File "/home/airflow/.local/lib/python3.8/site-packages/airflow/models/connection.py", line 479, in get_connection_from_secrets
    raise AirflowNotFoundException(f"The conn_id `{conn_id}` isn't defined")
airflow.exceptions.AirflowNotFoundException: The conn_id `postgres_conn` isn't defined
[2024-01-10T13:27:24.162+0000] {taskinstance.py:1138} INFO - Marking task as UP_FOR_RETRY. dag_id=weather_dag_2, task_id=group_a.tsk_truncate_table, execution_date=20240109T000000, start_date=20240110T132723, end_date=20240110T132724
[2024-01-10T13:27:24.174+0000] {standard_task_runner.py:107} ERROR - Failed to execute job 3 for task group_a.tsk_truncate_table (The conn_id `postgres_conn` isn't defined; 2489)
[2024-01-10T13:27:24.221+0000] {local_task_job_runner.py:234} INFO - Task exited with return code 1
[2024-01-10T13:27:24.237+0000] {taskinstance.py:3281} INFO - 0 downstream tasks scheduled from follow-on schedule check
